Workbook

Sheet Informacion STE
A1: Caracteristicas de la Suerte | G1: HACIENDA | H1: SUERTE | I1: TENENCIA | J1: AREA | K1: F.CORTE | L1: TCH | M1: N CORTE | N1: MAPA PRODUCTIVIDAD | O1: VARIEDAD
A2: Hacienda
A3: Suerte
A4: Area
A5: # Cortes
A6: Fecha de Siembra
A7: Edad Hoy
A8: Variedad
A9: Zona
A10: Mayordomo
A11: Zona Agroecologica
A12: TCH Actual | D12: =B13*1.2 -> 0
A13: TCH Maximo historico | D13: =B14*1.2 -> 0
A14: TCH Promedio

Sheet Resultado Analisis suelos 
A1: Zona | B1: 1 | C1: 2 | F1: NIVELES DE FERTILIDAD PARA RECOMENDACIÓN EN CAÑA DE AZUCAR | N1: Niveles de interpretacion de relaciones iónicas en resultados de análisis de suelos
A2: Area(Ha) | N2: Relaciones iónicas | O2: Ideal | P2: Rango critico | Q2: Deficiencia
A3: TCH_mean | N3: Ca/Mg | O3: 3 - 4 | P3: <3 | Q3: Calcio
A4: Arc_mean | F4: ELEMENTO | G4: UNIDAD | H4: BAJO | I4: NORMAL | J4: ALTO | K4: DATO Analisis | L4: Calificacion | P4: >4 | Q4: Magnesio
A5: Aren_mean | N5: Mg/K | O5: 6 - 8 | P5: >10 | Q5: Potasio
A6: Lim_mean | F6: Textura | P6: <5 | Q6: Magnesio
A7: pH_mean | F7: PH | N7: Na/K | O7: 0,5 - 1 | P7: >1 | Q7: Potasio
A8: MO%_mean | F8: MO | G8: % | H8: < 2.0 | I8: ( 2 - 4) | J8: >4.0 | N8: Ca/K | P8: >15 | Q8: Potasio
A9: CIC_mean | F9: C.I.C | G9: me/100 g | H9: < 10 | I9: (10 - 20) | J9: >20 | P9: <10 | Q9: Calcio
A10: Ca_mean | F10: Ca | G10: me/100 g | H10: <3.0 | I10: ( 3 - 6 ) | J10: >6.0 | N10: Ca+Mg/K | O10: 12 - 20 | P10: >25 | Q10: Potasio
A11: Cu_mean | F11: Cu | G11: ppm | H11: < 1.0 | I11: ( 1 - 3) | J11: >3.0 | P11: <10 | Q11: Calcio y/o Magnesio
A12: Fe_mean | F12: Fe | G12: ppm | H12: <30 | I12: (30 - 50) | J12: >50 | N12: Ca/B | O12: 1000 - 2000 | P12: >2000 | Q12: Boro
A13: K_mean | F13: K | G13: me/100 g | H13: <0.20 | I13: (0.20 - 0.40) | J13: >0.40 | N13: Fe/Mn | O13: 8 - 10 | P13: >10 | Q13: Manganeso
A14: Mg_mean | F14: Mg | G14: me/100 g | H14: < 1.5 | I14: (1.5 - 2.5) | J14: >2.5 | P14: <8 | Q14: Hierro
A15: Mn_mean | F15: Mn | G15: ppm | H15: <20 | I15: (20 - 40) | J15: >40 | N15: P/Zn | O15: 8 - 10 | P15: >12 | Q15: Zinc
A16: Na_mean | F16: Na | G16: me/100 g | H16: <0.5 | I16: 0.5 | J16: >0.50 | P16: <8 | Q16: Fosforo
A17: P_mean | F17: P | G17: ppm | H17: < 5.0 | I17: ( 5 - 10) | J17: >10 | N17: Fe/Zn | O17: 13 - 15 | P17: >15 | Q17: Zinc
A18: CE_mean | F18: S | G18: ppm | H18: < 6.0 | I18: ( 6 - 12 ) | J18: >12.0 | P18: <13 | Q18: Hierro
A19: Zn_mean | F19: Zn | G19: ppm | H19: < 1.0 | I19: ( 1 - 1.5) | J19: >1.5 | N19: Adaptado de Castro y Gomez 2010
A20: B_mean | F20: B | G20: ppm | H20: < 0.40 | I20: (0.40 - 0.5) | J20: >0.5
A21: Ca/Mg | B21: =B10/B14 -> #DIV/0! | C21: =C10/C14 -> #DIV/0! | F21: Mb | G21: me/100 g | H21: <0.1 | I21: 0.1 | J21: >0.1
A22: Mg/K | B22: =B14/B13 -> #DIV/0! | C22: =C14/C13 -> #DIV/0! | F22: Al | G22: me/100 g | H22: < 1.0 | I22: ( 1 - 2) | J22: >2.0
A23: Na/K | B23: =B16/B13 -> #DIV/0! | C23: =C16/C13 -> #DIV/0! | F23: Co | G23: ppm | H23: <0.7 | I23: (0.7 - 1.0) | J23: >1.0
A24: Ca/K | B24: =B10/B13 -> #DIV/0! | C24: =C10/C13 -> #DIV/0! | F24: CE | G24: dS/cm | H24: < 2.0 | I24: ( 2 - 4) | J24: >4.0
A25: Ca+Mg/K | B25: =(B10+B14)/B13 -> #DIV/0! | C25: =(C10+C14)/C13 -> #DIV/0! | F25: Ca/Mg | H25: 0-2 | I25: 2 - 3 | J25: > 3
A26: Fe/Mn | B26: =B12/B15 -> #DIV/0! | C26: =C12/C15 -> #DIV/0!
A27: P/Zn | B27: =B17/B19 -> #DIV/0! | C27: =C17/C19 -> #DIV/0!
A28: Fe/Zn | B28: =B12/B19 -> #DIV/0! | C28: =C12/C19 -> #DIV/0!
A29: K/Mg | B29: =B13/B14 -> #DIV/0! | C29: =C13/C14 -> #DIV/0!
F30: CALIFICACION DE TEXTURA
F31: Textura | I31: Calificacion
B32: 44.407746 | C32: 66.367487 | F32: 1 | G32: Arcillosa | H32: Ar | I32: Fino - pesado
F33: 2 | G33: Arcillo Arenosa | H33: ArA | I33: Fino sobre arenoso
F34: 3 | G34: Arcillo Limoso | H34: ArL | I34: Fino sobre arcilloso
F35: 4 | G35: Franco Arcilloso | H35: Far | I35: Medio
F36: 5 | G36: Franco Arcillo Limoso | H36: FArL | I36: Franco Fino Sobre Fino
F37: 6 | G37: Franco Arcillo Arenoso | H37: FArA | I37: Franco fino sobre grueso
F38: 7 | G38: Franco | H38: F | I38: Suelto
F39: 8 | G39: Franco Arenoso | H39: FA | I39: Franco grueso
F40: 9 | G40: Franco Limoso | H40: FL | I40: Franco Fino
...

Sheet Determinacion de Dosis
A1: Calculo de Nitrogeno | M1: Mezcla de Productos
A2: Suerte | B2: Zona | C2: Area Ha | D2: Productividad Est (ton/ha) | E2: M.O | F2: Cantidad de M.O (ton/ha) | G2: Kg/ha [N] disponible suelo | H2: Kg/ha [N] demandado | I2: Dosis (Kg/ha [N]) | J2: Fertilizante | K2: Kg Fert/Ha | L2: Dosis Plantilla (Kg/Ha) | M2: Fertilizante | N2: Kg Fert/Ha | O2: Dosis Plantilla (Kg/Ha) | S2: Resumen de Apicacion
B3: 1 | C3: ='Resultado Analisis suelos '!B$2 -> 0 | D3: ='Resultado Analisis suelos '!$B$3 -> 0 | E3: ='Resultado Analisis suelos '!B$8/100 -> 0 | F3: =ROUND('Parametros de referencia'!$C$3*('Parametros de referencia'!$C$9*'Parametros de referencia'!$C$4)*(E3),1) -> 0 | G3: =F$3*'Parametros de referencia'!$C$10*('Parametros de referencia'!$C$5)*('Parametros de referencia'!$C$6) * 'Parametros de referencia'!C$7 -> 0 | H3: =D3*'Parametros de referencia'!L$4 -> 0 | I3: =(H$3-G$3) -> 0 | J3: UREA ESPECIFICACION | K3: =IF(J$3="UREA ESPECIFICACION",((I$3/'Parametros de referencia'!$V$3)/'Parametros de referencia'!AI$3),IF(J$3="SULFATO AMONIO-CAMPO ESPEC",((I$3/'Parametros de referencia'!V$10)/'Parametros de referencia'!AI$10),IF(J$3="NITRO XTEND",((I$3/'Parametros de referencia'!V$13)/'Parametros de referencia'!AI$13)))) -> #DIV/0! | M3: SULFATO AMONIO-CAMPO ESPEC | N3: =IF($M$3="UREA ESPECIFICACION",((I$3/'Parametros de referencia'!$V$3)/'Parametros de referencia'!AI$3),IF($M$3="SULFATO AMONIO-CAMPO ESPEC",((I$3/'Parametros de referencia'!V$10)/'Parametros de referencia'!AI$10),IF($M$3="NITRO XTEND",((I$3/'Parametros de referencia'!V$13)/'Parametros de referencia'!AI$13))))*0.3 -> 0 | S3: Producto | T3: Zona 1 | U3: Zona 2 | V3: Dosis resrva
B4: 2 | C4: ='Resultado Analisis suelos '!C$2 -> 0 | D4: ='Resultado Analisis suelos '!C$3 -> 0 | E4: ='Resultado Analisis suelos '!C$8/100 -> 0 | F4: =ROUND('Parametros de referencia'!$C$3*('Parametros de referencia'!$C$9*'Parametros de referencia'!$C$4)*(E4),1) -> 0 | G4: =F$4*'Parametros de referencia'!$C$10*('Parametros de referencia'!$C$5)*('Parametros de referencia'!$C$6) * 'Parametros de referencia'!C$7 -> 0 | H4: =D4*'Parametros de referencia'!L$4 -> 0 | I4: =(H$4-G$4) -> 0 | J4: UREA ESPECIFICACION | K4: =IF(J$4="UREA ESPECIFICACION",((I$4/'Parametros de referencia'!$V$3)/'Parametros de referencia'!AI$3),IF(J$4="SULFATO AMONIO-CAMPO ESPEC",((I$4/'Parametros de referencia'!V$10)/'Parametros de referencia'!AI$10),IF(J$4="NITRO XTEND",((I$4/'Parametros de referencia'!V$13)/'Parametros de referencia'!AI$13)))) -> #DIV/0! | M4: SULFATO AMONIO-CAMPO ESPEC | N4: =IF(M$4="UREA ESPECIFICACION",((I$4/'Parametros de referencia'!$V$3)/'Parametros de referencia'!AI$3),IF(M$4="SULFATO AMONIO-CAMPO ESPEC",((I$4/'Parametros de referencia'!V$10)/'Parametros de referencia'!AI$10),IF(M$4="NITRO XTEND",((I$4/'Parametros de referencia'!V$13)/'Parametros de referencia'!AI$13))))*0.3 -> 0 | S4: AREA | T4: =C3 -> 0 | U4: =C4 -> 0 | V4: Kg producto | W4: Dosis unificada
S5: =J3 -> UREA ESPECIFICACION | T5: =L3 -> 0 | U5: =L4 -> 0 | V5: =($T$4*T5)+($U$4*U5) -> 0 | W5: =V5/(SUM($T$4:$U$4)) -> #DIV/0!
A6: Calculo de Fosforo | S6: =J14 -> CLORURO DE POTASIO ESPECIFI | T6: =R14 -> #DIV/0! | U6: =R15 -> #DIV/0! | V6: =($T$4*T6)+($U$4*U6) -> #DIV/0! | W6: =V6/(SUM($T$4:$U$4)) -> #DIV/0!
A7: Suerte | B7: Zona | C7: Area Ha | D7: Productividad Est (ton/ha) | E7: P (ppm) | G7: Kg/ha [P] disponible suelo | H7: Kg/ha [P] demandado | I7: Dosis (Kg/ha [P]) | J7: Fertilizante | K7: Kg Fert/Ha | L7: Dosis Plantilla (Kg/Ha) | S7: MENORES | T7: 50 | U7: 50 | V7: =($T$4*T7)+($U$4*U7) -> 0 | W7: =V7/(SUM($T$4:$U$4)) -> #DIV/0!
A8: =A3 -> 0 | B8: 1 | C8: =C$3 -> 0 | D8: =D$3 -> 0 | E8: ='Resultado Analisis suelos '!B$17 -> 0 | G8: ='Parametros de referencia'!C$3*('Parametros de referencia'!$C$9*'Parametros de referencia'!C$4)*'Parametros de referencia'!$C$10*(E$8/'Parametros de referencia'!$C$17)*0.3 -> 0 | H8: =D8*'Parametros de referencia'!$L$5 -> 0 | I8: =(H$8-G$8) -> 0 | J8: FOSFATO MONOAMÓNICO (MAP) | K8: =IF(J$8="FOSFATO DIAMONICO (DAP)",(($I$8/'Parametros de referencia'!$W$14)/'Parametros de referencia'!AI$14),IF(J$8="FOSQUIMINT VEINTE-8",((I$8/'Parametros de referencia'!W$9)/'Parametros de referencia'!AI$9),IF(J$8="FOSFATO MONOAMÓNICO (MAP)",(($I$8/'Parametros de referencia'!$W$16)/'Parametros de referencia'!AI$16)))) -> #DIV/0! | L8: =K8*0.8 -> #DIV/0!
B9: 2 | C9: =C$4 -> 0 | D9: =D$4 -> 0 | E9: ='Resultado Analisis suelos '!C$17 -> 0 | G9: ='Parametros de referencia'!C$3*('Parametros de referencia'!$C$9*'Parametros de referencia'!C$4)*'Parametros de referencia'!$C$10*(E$9/'Parametros de referencia'!$C$17)*0.3 -> 0 | H9: =D9*'Parametros de referencia'!$L$5 -> 0 | I9: =(H$9-G$9) -> 0 | J9: FOSFATO MONOAMÓNICO (MAP) | K9: =IF(J$9="FOSFATO DIAMONICO (DAP)",(($I$9/'Parametros de referencia'!$W$14)/'Parametros de referencia'!AI$14),IF(J$9="FOSQUIMINT VEINTE-8",((I$9/'Parametros de referencia'!W$9)/'Parametros de referencia'!AI$9),IF(J$9="FOSFATO MONOAMÓNICO (MAP)",(($I$9/'Parametros de referencia'!$W$16)/'Parametros de referencia'!AI$16)))) -> #DIV/0! | L9: =K9*0.8 -> #DIV/0!
A12: Calculo de Potasio | O12: Dosificacion de Potasio por Extraccion
A13: Suerte | B13: Zona | C13: Area Ha | D13: Productividad Est (ton/ha) | E13: K (meq/100 g suelo) | F13: ppm [K] disponible suelo | G13: Kg/ha [K] disponible suelo | H13: Kg/ha [K] demandado | I13: Dosis (Kg/ha [K]) | J13: Fertilizante | K13: Kg Fert/Ha | L13: Dosis Plantilla (Kg/Ha) | O13: Kg/ha [K] Demandado | P13: Dosis | Q13: Kg/ha [Fertilizante] | R13: Dosis Plantilla(Kg/Ha)
A14: =A3 -> 0 | B14: 1 | C14: =C$3 -> 0 | D14: =D$3 -> 0 | E14: ='Resultado Analisis suelos '!B$13 -> 0 | F14: =E14*'Parametros de referencia'!$C$11 -> 0 | G14: ='Parametros de referencia'!C$3*('Parametros de referencia'!$C$9*'Parametros de referencia'!C$4)*'Parametros de referencia'!$C$10*(F$14/'Parametros de referencia'!$C$17) -> 0 | H14: =D14*'Parametros de referencia'!$L$6 -> 0 | I14: =(H$14-G14) -> 0 | J14: CLORURO DE POTASIO ESPECIFI | K14: =IF(J$14="CLORURO DE POTASIO ESPECIFI",(($I$14/'Parametros de referencia'!$X$7)/'Parametros de referencia'!AI$7),0) -> #DIV/0! | L14: =$K$14*0.7-50 -> #DIV/0! | O14: =D14*'Parametros de referencia'!$L$6 -> 0 | P14: =IF('Resultado Analisis suelos '!$B$25<40,"No Aplicar",IF(AND('Resultado Analisis suelos '!$B$25>40,'Resultado Analisis suelos '!$B$25<70),'Determinacion de Dosis'!O14*0.15,IF('Resultado Analisis suelos '!$B$25>=70,0.2*'Determinacion de Dosis'!O14,0))) -> #DIV/0! | Q14: =IF(J$14="CLORURO DE POTASIO ESPECIFI",(($P$14/'Parametros de referencia'!$X$7)/'Parametros de referencia'!AI$7),0)-50 -> #DIV/0! | R14: =Q14*0.8 -> #DIV/0!
B15: 2 | C15: =C$4 -> 0 | D15: =D$4 -> 0 | E15: ='Resultado Analisis suelos '!C$13 -> 0 | F15: =E15*'Parametros de referencia'!$C$11 -> 0 | G15: ='Parametros de referencia'!C$3*('Parametros de referencia'!$C$9*'Parametros de referencia'!C$4)*'Parametros de referencia'!$C$10*(F$15/'Parametros de referencia'!$C$17) -> 0 | H15: =D15*'Parametros de referencia'!$L$6 -> 0 | I15: =(H15-G15) -> 0 | J15: CLORURO DE POTASIO ESPECIFI | K15: =IF(J$15="CLORURO DE POTASIO ESPECIFI",(($I$15/'Parametros de referencia'!$X$7)/'Parametros de referencia'!AI$7),0) -> #DIV/0! | L15: =$K$15*0.7-50 -> #DIV/0! | O15: =D15*'Parametros de referencia'!$L$6 -> 0 | P15: =IF('Resultado Analisis suelos '!$C$25<40,"No Aplicar",IF(AND('Resultado Analisis suelos '!$C$25>40,'Resultado Analisis suelos '!$C$25<70),'Determinacion de Dosis'!O15*0.15,IF('Resultado Analisis suelos '!$C$25>=70,0.2*'Determinacion de Dosis'!O15,0))) -> #DIV/0! | Q15: =IF(J$15="CLORURO DE POTASIO ESPECIFI",(($P$15/'Parametros de referencia'!$X$7)/'Parametros de referencia'!AI$7),0)-50 -> #DIV/0! | R15: =Q15*0.8 -> #DIV/0!
A17: Calculo de Boro
A18: Suerte | B18: Zona | C18: Area Ha | D18: Productividad Est (ton/ha) | E18: P (ppm) | G18: Kg [B] /ha disponible suelo | H18: Kg/ha [B] demandado | I18: Dosis (Kg/ha [B]) | J18: Fertilizante | K18: Kg Fert/Ha | L18: Dosis Plantilla (Kg/Ha)
A19: =A3 -> 0 | B19: 1 | C19: =C$3 -> 0 | D19: =D$3 -> 0 | E19: ='Resultado Analisis suelos '!B$20 -> 0 | G19: ='Parametros de referencia'!C$3*('Parametros de referencia'!$C$9*'Parametros de referencia'!C$4)*'Parametros de referencia'!$C$10*(E$19/'Parametros de referencia'!$C$17) -> 0 | H19: =(D19*'Parametros de referencia'!L$15)/1000 -> 0 | I19: =(H19-G19) -> 0 | J19: ZINCOFERTIL X 20KG | K19: =IF(J$19="ZINCOFERTIL X 20KG",((I$19/'Parametros de referencia'!$AD$4)/'Parametros de referencia'!AI$4),IF(J$19="MICROFERTIL X 46KG",((I$19/'Parametros de referencia'!AD$5)/'Parametros de referencia'!AI$5),IF(J$19="BOROZINCO",((I$19/'Parametros de referencia'!AD$6)/'Parametros de referencia'!AI$6),IF(J$19="FERTICANA ESPECIFICACION",((I$19/'Parametros de referencia'!$AD$8)/'Parametros de referencia'!$AI$8),0)))) -> 0 | L19: =$K$19*0.7 -> 0
B20: 2 | C20: =C$4 -> 0 | D20: =D$4 -> 0 | E20: ='Resultado Analisis suelos '!C$20 -> 0 | G20: ='Parametros de referencia'!C$3*('Parametros de referencia'!$C$9*'Parametros de referencia'!C$4)*'Parametros de referencia'!$C$10*(E$20/'Parametros de referencia'!$C$17) -> 0 | H20: =(D20*'Parametros de referencia'!L$15)/1000 -> 0 | I20: =(H20-G20) -> 0 | J20: ZINCOFERTIL X 20KG | K20: =IF(J$20="ZINCOFERTIL X 20KG",((I$20/'Parametros de referencia'!$AD$4)/'Parametros de referencia'!AI$4),IF(J$20="MICROFERTIL X 46KG",((I$20/'Parametros de referencia'!AD$5)/'Parametros de referencia'!AI$5),IF(J$20="BOROZINCO",((I$20/'Parametros de referencia'!AD$6)/'Parametros de referencia'!AI$6),IF(J$20="FERTICANA ESPECIFICACION",((I$20/'Parametros de referencia'!$AD$8)/'Parametros de referencia'!$AI$8),0)))) -> 0 | L20: =$K$20*0.7 -> 0
A23: Calculo de Zinc
A24: Suerte | B24: Zona | C24: Area Ha | D24: Productividad Est (ton/ha) | E24: P (ppm) | G24: Kg [Zn] /ha disponible suelo | H24: Kg/ha [Zn] demandado | I24: Dosis (Kg/ha [Zn]) | J24: Fertilizante | K24: Kg Fert/Ha | L24: Dosis Plantilla (Kg/Ha)
A25: =A3 -> 0 | B25: 1 | C25: =C$3 -> 0 | D25: =D$3 -> 0 | E25: ='Resultado Analisis suelos '!B$19 -> 0 | G25: ='Parametros de referencia'!C$3*('Parametros de referencia'!$C$9*'Parametros de referencia'!C$4)*'Parametros de referencia'!$C$10*(E$25/'Parametros de referencia'!$C$17) -> 0 | H25: =($D$25*'Parametros de referencia'!L$14)/1000 -> 0 | I25: =(H25-G25) -> 0 | J25: ZINCOFERTIL X 20KG | K25: =IF(J$25="ZINCOFERTIL X 20KG",((I$25/'Parametros de referencia'!$AF$4)/'Parametros de referencia'!AI$4),IF(J$25="MICROFERTIL X 46KG",((I$25/'Parametros de referencia'!AF$5)/'Parametros de referencia'!AI$5),IF(J$25="BOROZINCO",((I$25/'Parametros de referencia'!AF$6)/'Parametros de referencia'!AI$6),IF(J$25="FERTICANA ESPECIFICACION",((I$25/'Parametros de referencia'!$AF$8)/'Parametros de referencia'!$AI$8),0)))) -> 0 | L25: =$K$25*0.7 -> 0
B26: 2 | C26: =C$4 -> 0 | D26: =D$4 -> 0 | E26: ='Resultado Analisis suelos '!C$19 -> 0 | G26: ='Parametros de referencia'!C$3*('Parametros de referencia'!$C$9*'Parametros de referencia'!C$4)*'Parametros de referencia'!$C$10*(E$26/'Parametros de referencia'!$C$17) -> 0 | H26: =(D26*'Parametros de referencia'!L$14)/1000 -> 0 | I26: =(H26-G26) -> 0 | J26: ZINCOFERTIL X 20KG | K26: =IF(J$26="ZINCOFERTIL X 20KG",((I$26/'Parametros de referencia'!$AF$4)/'Parametros de referencia'!AI$4),IF(J$26="MICROFERTIL X 46KG",((I$26/'Parametros de referencia'!AF$5)/'Parametros de referencia'!AI$5),IF(J$26="BOROZINCO",((I$26/'Parametros de referencia'!AF$6)/'Parametros de referencia'!AI$6),IF(J$26="FERTICANA ESPECIFICACION",((I$26/'Parametros de referencia'!$AF$8)/'Parametros de referencia'!$AI$8),0)))) -> 0 | L26: =$K$26*0.7 -> 0
A28: Calculo de Hierro
A29: Suerte | B29: Zona | C29: Area Ha | D29: Productividad Est (ton/ha) | E29: P (ppm) | G29: Kg [Zn] /ha disponible suelo | H29: Kg/ha [Zn] demandado | I29: Dosis (Kg/ha [Zn]) | J29: Fertilizante | K29: Kg Fert/Ha | L29: Dosis Plantilla (Kg/Ha)
A30: =A3 -> 0 | B30: 1 | C30: =C$3 -> 0 | D30: =D$3 -> 0 | E30: ='Resultado Analisis suelos '!B$12 -> 0 | G30: ='Parametros de referencia'!C$3*('Parametros de referencia'!$C$9*'Parametros de referencia'!C$4)*'Parametros de referencia'!$C$10*(E$30/'Parametros de referencia'!$C$17) -> 0 | H30: =(D30*'Parametros de referencia'!$L$11)/1000 -> 0 | I30: =(H30-G30) -> 0 | J30: ZINCOFERTIL X 20KG | K30: =IF(J$25="ZINCOFERTIL X 20KG",((I$25/'Parametros de referencia'!$AF$4)/'Parametros de referencia'!AI$4),IF(J$25="MICROFERTIL X 46KG",((I$25/'Parametros de referencia'!AF$5)/'Parametros de referencia'!AI$5),IF(J$25="BOROZINCO",((I$25/'Parametros de referencia'!AF$6)/'Parametros de referencia'!AI$6),IF(J$25="FERTICANA ESPECIFICACION",((I$25/'Parametros de referencia'!$AF$8)/'Parametros de referencia'!$AI$8),0)))) -> 0 | L30: =$K$25*0.7 -> 0
B31: 2 | C31: =C$4 -> 0 | D31: =D$4 -> 0 | E31: ='Resultado Analisis suelos '!C$12 -> 0 | G31: ='Parametros de referencia'!C$3*('Parametros de referencia'!$C$9*'Parametros de referencia'!C$4)*'Parametros de referencia'!$C$10*(E$31/'Parametros de referencia'!$C$17) -> 0 | H31: =(D31*'Parametros de referencia'!$L$11)/1000 -> 0 | I31: =(H31-G31)/1000 -> 0 | J31: ZINCOFERTIL X 20KG | K31: =IF(J$26="ZINCOFERTIL X 20KG",((I$26/'Parametros de referencia'!$AF$4)/'Parametros de referencia'!AI$4),IF(J$26="MICROFERTIL X 46KG",((I$26/'Parametros de referencia'!AF$5)/'Parametros de referencia'!AI$5),IF(J$26="BOROZINCO",((I$26/'Parametros de referencia'!AF$6)/'Parametros de referencia'!AI$6),IF(J$26="FERTICANA ESPECIFICACION",((I$26/'Parametros de referencia'!$AF$8)/'Parametros de referencia'!$AI$8),0)))) -> 0 | L31: =$K$26*0.7 -> 0

Sheet Parametros de referencia
B1: Parametros del Suelo | F1: Factor de extraccion por Variedad | N1: Eficiencia de Fertilizantes Comité de AP | U1: Parametros Fertilizates | AI1: Eficiencias Seleccionada | AJ1: Eficiencias | AL1: Observaciones
B2: Parametros de referencia | C2: Valor | D2: Unidad | F2: Mayores (Kg / THC) | N2: Urea | P2: DAP | R2: K | U2: Fertilizante/ Nutrimento | V2: N | W2: P | X2: K | Y2: S | Z2: Ca | AA2: Si | AB2: C | AC2: Mg | AD2: B | AE2: Fe | AF2: Zn | AG2: Cu | AH2: Cl | AJ2: Alta | AK2: Baja
B3: Densidad aparente del suelo (ρ) | C3: 1.2 | D3: Ton/m3 | F3: Nutriente / Variedad | G3: CC 01-1940 | H3: CC 01-678 | I3: CC 05-430 | J3: CC 85-92 | K3: CC 93-4418 | L3: Promedio | N3: pH | P3: Ph | R3: (Ca+Mg)/K | U3: UREA ESPECIFICACION | V3: 0.46 | W3: - | X3: - | Y3: - | Z3: - | AA3: - | AB3: - | AC3: - | AD3: - | AE3: - | AF3: - | AG3: - | AH3: - | AI3: =IF(AND(AVERAGE('Resultado Analisis suelos '!B7:C7)>=6.5,AVERAGE('Resultado Analisis suelos '!B7:C7)<=7.5),'Parametros de referencia'!AJ3,'Parametros de referencia'!AK3) -> #DIV/0! | AJ3: 0.9 | AK3: 0.75 | AL3: Variacion por pH
B4: Profundidad de extraccion (h) | C4: 0.2 | D4: m | F4: Nitrogeno | G4: 0.82 | H4: 0.76 | I4: 0.68 | J4: 1.03 | K4: 1.18 | L4: 1.3 | N4: N Acido | O4: Salino | P4: 6,5 - 7,5 | Q4: >7,5 o ><6,5> | R4: >70 | S4: <70 | U4: ZINCOFERTIL X 20KG | V4: - | W4: - | X4: 0.03 | Y4: 0.06 | Z4: - | AA4: 0.18 | AB4: 0.094 | AC4: - | AD4: 0.03 | AE4: - | AF4: 0.15 | AG4: 0.006 | AH4: - | AI4: 1 | AJ4: 1 | AK4: 1
B5: Cantidad de N en la M.O | C5: 0.05 | D5: % | F5: Fosforo | G5: 0.17 | H5: 0.11 | I5: 0.11 | J5: 0.22 | K5: 0.24 | L5: 0.2 | N5: 0.8 | O5: 0.75 | P5: 0.5 | Q5: 0.3 | R5: 0.5 | S5: 0.75 | U5: MICROFERTIL X 46KG | V5: - | W5: 0.05 | X5: - | Y5: 0.058 | Z5: 0.18 | AA5: 0.25 | AB5: 0.05 | AC5: 0.03 | AD5: 0.01 | AE5: 0.01 | AF5: 0.03 | AG5: 0.002 | AH5: - | AI5: 1 | AJ5: 1 | AK5: 1
B6: Tasa de mineralizacion del N | C6: 0.01 | D6: % | F6: Potasio | G6: 1.01 | H6: 1.13 | I6: 1.05 | J6: 1.43 | K6: 1.51 | L6: 2.5 | U6: BOROZINCO | V6: 0.03 | W6: - | X6: - | Y6: 0.06 | Z6: - | AA6: 0.17 | AB6: - | AC6: - | AD6: 0.025 | AE6: - | AF6: 0.15 | AG6: 0.005 | AH6: - | AI6: 1 | AJ6: 1 | AK6: 1
B7: Absorcion de N del suelos | C7: 0.5 | D7: % | F7: Magnesio | G7: 0.2 | H7: 0.15 | I7: 0.15 | J7: 0.27 | K7: 0.32 | L7: 0.3 | N7: SULFATO AMONIO | P7: P | R7: K | U7: CLORURO DE POTASIO ESPECIFI | V7: - | W7: - | X7: 0.6 | Y7: - | Z7: - | AA7: - | AB7: - | AC7: - | AD7: - | AE7: - | AF7: - | AG7: - | AH7: 0.46 | AI7: =IF(AVERAGE('Resultado Analisis suelos '!B25:C25)<70,'Parametros de referencia'!AJ$7,'Parametros de referencia'!AK$7) -> #DIV/0! | AJ7: 0.75 | AK7: 0.5 | AL7: Variacion de Relacion (Ca+Mg)/K (>70) Alta - (<70) Baja
B8: Conversiones | F8: Calcio | G8: 0.41 | H8: 0.32 | I8: 0.34 | J8: 0.52 | K8: 0.64 | L8: 0.6 | N8: pH | P8: Ph | R8: (Ca+Mg)/K | U8: FERTICANA ESPECIFICACION | V8: - | W8: 0.03 | X8: 0.2 | Y8: 0.02 | Z8: 0.02 | AA8: - | AB8: - | AC8: 0.005 | AD8: 0.005 | AE8: 0.01 | AF8: 0.005 | AG8: - | AH8: - | AI8: 1 | AJ8: 1 | AK8: 1
B9: 1 Hectarea | C9: 10000 | D9: m2 | F9: Menores (gr/THC) | N9: N Acido | O9: Salino | P9: 6,5 - 7,5 | Q9: >7,5 o <6,5 | R9: >70 | S9: <70 | U9: FOSQUIMINT VEINTE-8 | V9: - | W9: 0.36 | X9: - | Z9: 0.25 | AA9: - | AB9: - | AC9: - | AD9: - | AE9: - | AF9: - | AG9: - | AH9: - | AI9: =IF(6.5<AVERAGE('Resultado Analisis suelos '!B7:C7)<7.5,'Parametros de referencia'!AJ9,'Parametros de referencia'!AK9) -> #DIV/0! | AJ9: 0.5 | AK9: 0.3
B10: 1 Tonelada | C10: 1000 | D10: Kg | F10: Azufre | G10: 0.08 | H10: 0.06 | I10: 0.05 | J10: 0.09 | K10: 0.06 | L10: =AVERAGE(G10:K10) -> 0.068 | N10: 0.8 | U10: SULFATO AMONIO-CAMPO ESPEC | V10: 0.21 | W10: - | X10: - | Y10: 0.24 | Z10: - | AA10: - | AB10: - | AC10: - | AD10: - | AE10: - | AF10: - | AG10: - | AH10: - | AI10: 1 | AJ10: 1 | AK10: 1
B11: 1 meq/100gr Suelo K+ | C11: 391 | D11: ppm | F11: Hierro | G11: 40.38 | H11: 36.62 | I11: 37.83 | J11: 66.1 | K11: 77.37 | L11: =AVERAGE(G11:K11) -> 51.66 | U11: SULFATO DE CALCIO ( YESO AGRICOLA) | V11: - | W11: - | X11: - | Y11: - | Z11: 0.26 | AA11: 0.012 | AB11: - | AC11: 0.014 | AD11: - | AE11: 0.001 | AF11: - | AG11: - | AH11: - | AI11: 1 | AJ11: 1 | AK11: 1
B12: 1 meq/100gr Suelo Ca+2 | C12: 200.4 | D12: ppm | F12: Manganeso | G12: 16.44 | H12: 3.38 | I12: 3.75 | J12: 19.03 | K12: 7.4 | L12: =AVERAGE(G12:K12) -> 10 | N12: NITRO XTEND | P12: P | R12: K | U12: NITRORGANIC FERT. ORGAN EMPRESAGRO | V12: 0.0466 | W12: 0.0305 | X12: 0.0302 | Y12: 0.03 | Z12: 0.1303 | AA12: 0.1674 | AB12: 0.2013 | AC12: - | AD12: - | AE12: - | AF12: - | AG12: - | AH12: - | AI12: 1 | AJ12: 1 | AK12: 1
B13: 1 meq/100gr Suelo Mg+2 | C13: 121.5 | D13: ppm | F13: Cobre | G13: 0.65 | H13: 0.46 | I13: 0.51 | J13: 0.78 | K13: 0.93 | L13: =AVERAGE(G13:K13) -> 0.666 | N13: pH | P13: Ph | R13: (Ca+Mg)/K | U13: NITRO XTEND | V13: 0.4 | W13: - | X13: - | Y13: 0.06 | Z13: - | AA13: - | AB13: - | AC13: - | AD13: - | AE13: - | AF13: - | AG13: - | AH13: - | AI13: =IF(6.5<AVERAGE('Resultado Analisis suelos '!B7:C7)<7.5,'Parametros de referencia'!AJ3,'Parametros de referencia'!AK3) -> #DIV/0! | AJ13: 0.9 | AK13: 0.75
B14: 1 meq/100gr Suelo Na+ | C14: 229 | D14: ppm | F14: Zinc | G14: 0.73 | H14: 0.92 | I14: 0.91 | J14: 1.25 | K14: 1.27 | L14: =AVERAGE(G14:K14) -> 1.016 | N14: N Acido | O14: Salino | P14: 6,5 - 7,5 | Q14: >7,5 o <6,5 | R14: >70 | S14: <70 | U14: FOSFATO DIAMONICO (DAP) | V14: 0.18 | W14: 0.46 | X14: - | Y14: - | Z14: - | AA14: - | AB14: - | AC14: - | AD14: - | AE14: - | AF14: - | AG14: - | AH14: - | AI14: =IF(AND(AVERAGE('Resultado Analisis suelos '!B7:C7)>=6.5,AVERAGE('Resultado Analisis suelos '!B7:C7)<=7.5),'Parametros de referencia'!AJ14,'Parametros de referencia'!AK14) -> #DIV/0! | AJ14: 0.5 | AK14: 0.3 | AL14: Variacion de pH (6,5-7,5) Alta - (>7,5 o <6,5) Baja
B15: 1 meq/100gr Suelo AL+3 | C15: 89.9 | D15: ppm | F15: Boro | G15: 0.47 | H15: 0.48 | I15: 0.43 | J15: 0.61 | K15: 0.67 | L15: =AVERAGE(G15:K15) -> 0.532 | N15: 0.9 | O15: 0.75 | P15: 0.5 | Q15: 0.3 | R15: 0.5 | S15: 0.75 | U15: SUPER FOSFATO TRIPLE | V15: - | W15: 0.46 | X15: - | Y15: - | Z15: - | AA15: - | AB15: - | AC15: - | AD15: - | AE15: - | AF15: - | AG15: - | AH15: - | AI15: =IF(6.5<AVERAGE('Resultado Analisis suelos '!B7:C7)<7.5,'Parametros de referencia'!AJ14,'Parametros de referencia'!AK14) -> #DIV/0! | AJ15: 0.5 | AK15: 0.3
B16: 1 meq/100gr Suelo Zn+2 | C16: 327 | D16: ppm | U16: FOSFATO MONOAMÓNICO (MAP) | V16: 0.1 | W16: 0.5 | AI16: =IF(AND(AVERAGE('Resultado Analisis suelos '!B7:C97)>=6.5,AVERAGE('Resultado Analisis suelos '!B7:C7)<=7.5),'Parametros de referencia'!AJ16,'Parametros de referencia'!AK16) -> #DIV/0! | AJ16: 0.5 | AK16: 0.3
B17: 1Kg | C17: 1000000 | D17: mg
U21: NITROGENO
U22: UREA ESPECIFICACION
U23: SULFATO AMONIO-CAMPO ESPEC
U24: NITRO XTEND
U26: FOSFORO
U27: FOSFATO DIAMONICO (DAP)
U28: FOSQUIMINT VEINTE-8
U29: FOSFATO MONOAMÓNICO (MAP)
U30: POTASIO
U31: CLORURO DE POTASIO ESPECIFI
U33: MENORES
U34: ZINCOFERTIL X 20KG
... U37: FERTICANA ESPECIFICACION
