Workbook

Sheet Informacion STE
A1: Caracteristicas de la Suerte | E1: Cod. | F1: Hacienda | G1: Ste | H1: Edad | I1: Variedad | J1: NC | K1: Fecha Liquidacion | L1: TCH | M1: Area
A2: Hacienda
A3: Suerte
A4: Area
A5: # Cortes
A6: Fecha de Siembra
A7: Edad Hoy | B7: =(TODAY()-B6)/30 -> 1517.9333
A8: Variedad
A9: Zona
A10: Mayordomo
A11: Zona Agroecologica
A12: TCH Actual
A13: TCH Promedio Ciclo
A14: TCH Promedio
B17: Actual +20% | C17: =B12*1.2 -> 0
B18: Ppromedio Ciclo + 20% | C18: =B13*1.2 -> 0
B19: Promedio + 20% | C19: =B14*1.2 -> 0

Sheet Resultado Analisis suelos 
A1: Zona | B1: 1 | C1: 2 | D1: 3 | G1: NIVELES DE FERTILIDAD PARA RECOMENDACIÓN EN CAÑA DE AZUCAR | O1: Niveles de interpretacion de relaciones iónicas en resultados de análisis de suelos
A2: Area(Ha) | O2: Relaciones iónicas | P2: Ideal | Q2: Rango critico | R2: Deficiencia
A3: TCH_mean | O3: Ca/Mg | P3: 3 - 4 | Q3: <3 | R3: Calcio
A4: Arc_mean | G4: ELEMENTO | H4: UNIDAD | I4: BAJO | J4: NORMAL | K4: ALTO | L4: DATO Analisis | M4: Calificacion | Q4: >4 | R4: Magnesio
A5: Aren_mean | O5: Mg/K | P5: 6 - 8 | Q5: >10 | R5: Potasio
A6: Lim_mean | G6: Textura | Q6: <5 | R6: Magnesio
A7: pH_mean | G7: PH | O7: Na/K | P7: 0,5 - 1 | Q7: >1 | R7: Potasio
A8: MO%_mean | G8: MO | H8: % | I8: < 2.0 | J8: ( 2 - 4) | K8: >4.0 | O8: Ca/K | Q8: >15 | R8: Potasio
A9: CIC_mean | G9: C.I.C | H9: me/100 g | I9: < 10 | J9: (10 - 20) | K9: >20 | Q9: <10 | R9: Calcio
A10: Ca_mean | G10: Ca | H10: me/100 g | I10: <3.0 | J10: ( 3 - 6 ) | K10: >6.0 | O10: Ca+Mg/K | P10: 12 - 20 | Q10: >25 | R10: Potasio
A11: Cu_mean | G11: Cu | H11: ppm | I11: < 1.0 | J11: ( 1 - 3) | K11: >3.0 | Q11: <10 | R11: Calcio y/o Magnesio
A12: Fe_mean | G12: Fe | H12: ppm | I12: <30 | J12: (30 - 50) | K12: >50 | O12: Ca/B | P12: 1000 - 2000 | Q12: >2000 | R12: Boro
A13: K_mean | G13: K | H13: me/100 g | I13: <0.20 | J13: (0.20 - 0.40) | K13: >0.40 | O13: Fe/Mn | P13: 8 - 10 | Q13: >10 | R13: Manganeso
A14: Mg_mean | G14: Mg | H14: me/100 g | I14: < 1.5 | J14: (1.5 - 2.5) | K14: >2.5 | Q14: <8 | R14: Hierro
A15: Mn_mean | G15: Mn | H15: ppm | I15: <20 | J15: (20 - 40) | K15: >40 | O15: P/Zn | P15: 8 - 10 | Q15: >12 | R15: Zinc
A16: Na_mean | G16: Na | H16: me/100 g | I16: <0.5 | J16: 0.5 | K16: >0.50 | Q16: <8 | R16: Fosforo
A17: P_mean | G17: P | H17: ppm | I17: < 5.0 | J17: ( 5 - 10) | K17: >10 | O17: Fe/Zn | P17: 13 - 15 | Q17: >15 | R17: Zinc
A18: S_mean | G18: S | H18: ppm | I18: < 6.0 | J18: ( 6 - 12 ) | K18: >12.0 | Q18: <13 | R18: Hierro
A19: Zn_mean | G19: Zn | H19: ppm | I19: < 1.0 | J19: ( 1 - 1.5) | K19: >1.5 | O19: Adaptado de Castro y Gomez 2010
A20: B_mean | G20: B | H20: ppm | I20: < 0.40 | J20: (0.40 - 0.5) | K20: >0.5
A21: Ca/Mg | B21: =B10/B14 -> #DIV/0! | C21: =C10/C14 -> #DIV/0! | D21: =D10/D14 -> #DIV/0! | G21: Mb | H21: me/100 g | I21: <0.1 | J21: 0.1 | K21: >0.1
A22: Mg/K | B22: =B14/B13 -> #DIV/0! | C22: =C14/C13 -> #DIV/0! | D22: =D14/D13 -> #DIV/0! | G22: Al | H22: me/100 g | I22: < 1.0 | J22: ( 1 - 2) | K22: >2.0
A23: Na/K | B23: =B16/B13 -> #DIV/0! | C23: =C16/C13 -> #DIV/0! | D23: =D16/D13 -> #DIV/0! | G23: Co | H23: ppm | I23: <0.7 | J23: (0.7 - 1.0) | K23: >1.0
A24: Ca/K | B24: =B10/B13 -> #DIV/0! | C24: =C10/C13 -> #DIV/0! | D24: =D10/D13 -> #DIV/0! | G24: CE | H24: dS/cm | I24: < 2.0 | J24: ( 2 - 4) | K24: >4.0
A25: Ca+Mg/K | B25: =(B10+B14)/B13 -> #DIV/0! | C25: =(C10+C14)/C13 -> #DIV/0! | D25: =(D10+D14)/D13 -> #DIV/0! | G25: Ca/Mg | I25: 0-2 | J25: 2 - 3 | K25: > 3
A26: Fe/Mn | B26: =B12/B15 -> #DIV/0! | C26: =C12/C15 -> #DIV/0! | D26: =D12/D15 -> #DIV/0!
A27: P/Zn | B27: =B17/B19 -> #DIV/0! | C27: =C17/C19 -> #DIV/0! | D27: =D17/D19 -> #DIV/0!
A28: Fe/Zn | B28: =B12/B19 -> #DIV/0! | C28: =C12/C19 -> #DIV/0! | D28: =D12/D19 -> #DIV/0!
A29: K/Mg | B29: =B13/B14 -> #DIV/0! | C29: =C13/C14 -> #DIV/0! | D29: =D13/D14 -> #DIV/0! | G29: CALIFICACION DE TEXTURA
H30: Textura
G31: 1 | H31: Arcillosa | J31: Calificacion
G32: 2 | H32: Arcillo Arenosa | I32: Ar | J32: Fino - pesado
G33: 3 | H33: Arcillo Limoso | I33: ArA | J33: Fino sobre arenoso
G34: 4 | H34: Franco Arcilloso | I34: ArL | J34: Fino sobre arcilloso
G35: 5 | H35: Franco Arcillo Limoso | I35: Far | J35: Medio
G36: 6 | H36: Franco Arcillo Arenoso | I36: FArL | J36: Franco Fino Sobre Fino
G37: 7 | H37: Franco | I37: FArA | J37: Franco fino sobre grueso
G38: 8 | H38: Franco Arenoso | I38: F | J38: Suelto
G39: 9 | H39: Franco Limoso | I39: FA | J39: Franco grueso
G40: 10 | H40: Arenoso Franco | I40: FL | J40: Franco Fino
...

Sheet Determinacion de Dosis
A1: Calculo de Nitrogeno | M1: Mezcla de Productos | R1: Resumen de Apicacion
A2: Suerte | B2: Zona | C2: Area Ha | D2: Productividad Est (ton/ha) | E2: M.O | F2: Cantidad de M.O (ton/ha) | G2: Kg/ha [N] disponible suelo | H2: Kg/ha [N] demandado | I2: Dosis (Kg/ha [N]) | J2: Fertilizante | K2: Kg Fert/Ha | L2: Dosis Plantilla (Kg/Ha) | M2: Fertilizante | N2: Kg Fert/Ha | O2: Dosis Plantilla (Kg/Ha) | R2: Producto | S2: Zona 1 | T2: Zona 2 | U2: Zona 3 | V2: Reserva
A3: 017002F | B3: 1 | C3: ='Resultado Analisis suelos '!B$2 -> 0 | D3: ='Resultado Analisis suelos '!B3 -> 0 | E3: ='Resultado Analisis suelos '!B$8/100 -> 0 | F3: =ROUND('Parametros de referencia'!$C$3*('Parametros de referencia'!$C$9*'Parametros de referencia'!$C$4)*(E3),1) -> 0 | G3: =F$3*'Parametros de referencia'!$C$10*('Parametros de referencia'!$C$5)*('Parametros de referencia'!$C$6) * 'Parametros de referencia'!C$7 -> 0 | H3: =D3*'Parametros de referencia'!L$4 -> 0 | I3: =(H$3-G$3) -> 0 | K3: =IF(J$3="UREA ESPECIFICACION",((I$3/'Parametros de referencia'!$V$3)/'Parametros de referencia'!AI$3),IF(J$3="SULFATO AMONIO-CAMPO ESPEC",((I$3/'Parametros de referencia'!V$10)/'Parametros de referencia'!AI$10),IF(J$3="NITRO XTEND",((I$3/'Parametros de referencia'!V$13)/'Parametros de referencia'!AI$13)))) -> FALSE | R3: AREA | S3: =C3 -> 0 | T3: =C4 -> 0 | U3: =C5 -> 0 | V3: Total Producto(Kg) | W3: Dosis Reserva(Kg/Ha)
B4: 2 | C4: ='Resultado Analisis suelos '!C$2 -> 0 | D4: 0 | E4: ='Resultado Analisis suelos '!C$8/100 -> 0 | F4: =ROUND('Parametros de referencia'!$C$3*('Parametros de referencia'!$C$9*'Parametros de referencia'!$C$4)*(E4),1) -> 0 | G4: =F$4*'Parametros de referencia'!$C$10*('Parametros de referencia'!$C$5)*('Parametros de referencia'!$C$6) * 'Parametros de referencia'!C$7 -> 0 | H4: =D4*'Parametros de referencia'!L$4 -> 0 | I4: =(H$4-G$4) -> 0 | K4: =IF(J$4="UREA ESPECIFICACION",((I$4/'Parametros de referencia'!$V$3)/'Parametros de referencia'!AI$3),IF(J$4="SULFATO AMONIO-CAMPO ESPEC",((I$4/'Parametros de referencia'!V$10)/'Parametros de referencia'!AI$10),IF(J$4="NITRO XTEND",((I$4/'Parametros de referencia'!V$13)/'Parametros de referencia'!AI$13)))) -> FALSE | R4: =J3 -> 0 | S4: =K3 -> FALSE | T4: =K4 -> FALSE | U4: =K5 -> FALSE | V4: =($S$3*S4)+($T$3*T4)+($U$3*U4) -> 0 | W4: =V4/SUM($S$3:$U$3) -> #DIV/0!
B5: 3 | C5: ='Resultado Analisis suelos '!D$2 -> 0 | D5: ='Resultado Analisis suelos '!D3 -> 0 | E5: ='Resultado Analisis suelos '!D$8/100 -> 0 | F5: =ROUND('Parametros de referencia'!$C$3*('Parametros de referencia'!$C$9*'Parametros de referencia'!$C$4)*(E5),1) -> 0 | G5: =F$5*'Parametros de referencia'!$C$10*('Parametros de referencia'!$C$5)*('Parametros de referencia'!$C$6) * 'Parametros de referencia'!C$7 -> 0 | H5: =D5*'Parametros de referencia'!L$4 -> 0 | I5: =(H$5-G$5) -> 0 | K5: =IF(J$5="UREA ESPECIFICACION",((I$5/'Parametros de referencia'!$V$3)/'Parametros de referencia'!AI$3),IF(J$5="SULFATO AMONIO-CAMPO ESPEC",((I$5/'Parametros de referencia'!V$10)/'Parametros de referencia'!AI$10),IF(J$5="NITRO XTEND",((I$5/'Parametros de referencia'!V$13)/'Parametros de referencia'!AI$13)))) -> FALSE | R5: =J17 -> 0 | S5: =Q17 -> 0 | T5: =0 -> 0 | U5: 0 | V5: =($S$3*S5)+($T$3*T5)+($U$3*U5) -> 0 | W5: =V5/SUM($S$3:$U$3) -> #DIV/0!
R6: MENORES | S6: 50 | T6: 50 | U6: 50 | V6: =($S$3*S6)+($T$3*T6)+($U$3*U6) -> 0 | W6: =V6/SUM($S$3:$U$3) -> #DIV/0!
A8: Calculo de Fosforo
A9: Suerte | B9: Zona | C9: Area Ha | D9: Productividad Est (ton/ha) | E9: P (ppm) | G9: Kg/ha [P] disponible suelo | H9: Kg/ha [P] demandado | I9: Dosis (Kg/ha [P]) | J9: Fertilizante | K9: Kg Fert/Ha | L9: Dosis Plantilla (Kg/Ha)
A10: =A3 -> 017002F | B10: 1 | C10: =C$3 -> 0 | D10: =D$3 -> 0 | E10: ='Resultado Analisis suelos '!B$17 -> 0 | G10: ='Parametros de referencia'!C$3*('Parametros de referencia'!$C$9*'Parametros de referencia'!C$4)*'Parametros de referencia'!$C$10*(E$10/'Parametros de referencia'!$C$17) -> 0 | H10: =D10*'Parametros de referencia'!$L$5 -> 0 | I10: =(H$10-G$10) -> 0 | K10: =IF(J$10="FOSFATO DIAMONICO (DAP)",(($I$10/'Parametros de referencia'!$W$14)/'Parametros de referencia'!AI$14),IF(J$10="FOSQUIMINT VEINTE-8",((I$10/'Parametros de referencia'!W$9)/'Parametros de referencia'!AI$9))) -> FALSE | L10: =$K$10*0.7 -> 0
B11: 2 | C11: =C$4 -> 0 | D11: =D$4 -> 0 | E11: ='Resultado Analisis suelos '!C$17 -> 0 | G11: ='Parametros de referencia'!C$3*('Parametros de referencia'!$C$9*'Parametros de referencia'!C$4)*'Parametros de referencia'!$C$10*(E$11/'Parametros de referencia'!$C$17) -> 0 | H11: =D11*'Parametros de referencia'!$L$5 -> 0 | I11: =(H$11-G$11) -> 0 | K11: =IF(J$11="FOSFATO DIAMONICO (DAP)",((I$11/'Parametros de referencia'!$W$14)/'Parametros de referencia'!AI$14),IF(J$11="FOSQUIMINT VEINTE-8",((I$11/'Parametros de referencia'!W$9)/'Parametros de referencia'!AI$9),0)) -> 0 | L11: =$K$11*0.7 -> 0
B12: 3 | C12: =$C$5 -> 0 | D12: =D$5 -> 0 | E12: ='Resultado Analisis suelos '!D$17 -> 0 | G12: ='Parametros de referencia'!C$3*('Parametros de referencia'!$C$9*'Parametros de referencia'!C$4)*'Parametros de referencia'!$C$10*(E$12/'Parametros de referencia'!$C$17) -> 0 | H12: =D12*'Parametros de referencia'!$L$5 -> 0 | I12: =(H$12-G$12) -> 0 | K12: =IF(J$12="FOSFATO DIAMONICO (DAP)",((I$12/'Parametros de referencia'!$W$14)/'Parametros de referencia'!AI$14),IF(J$12="FOSQUIMINT VEINTE-8",((I$12/'Parametros de referencia'!W$9)/'Parametros de referencia'!AI$9),0)) -> 0 | L12: =$K$12*0.7 -> 0
A15: Calculo de Potasio | O15: Dosificacion de Potacio por Extraccion
A16: Suerte | B16: Zona | C16: Area Ha | D16: Productividad Est (ton/ha) | E16: K (meq/100 g suelo) | F16: ppm [K] disponible suelo | G16: Kg/ha [K] disponible suelo | H16: Kg/ha [K] demandado | I16: Dosis (Kg/ha [K]) | J16: Fertilizante | K16: Kg Fert/Ha | L16: Dosis Plantilla (Kg/Ha) | M16: Dosis Convencional (Kg/Ha) | O16: Kg/ha [K] Demandado | P16: Dosis | Q16: Kg/ha [Fertilizante]
A17: =A10 -> 017002F | B17: 1 | C17: =C$3 -> 0 | D17: =D$3 -> 0 | E17: ='Resultado Analisis suelos '!B$13 -> 0 | F17: =E17*'Parametros de referencia'!$C$11 -> 0 | G17: ='Parametros de referencia'!C$3*('Parametros de referencia'!$C$9*'Parametros de referencia'!C$4)*'Parametros de referencia'!$C$10*(F$17/'Parametros de referencia'!$C$17) -> 0 | H17: =D17*'Parametros de referencia'!$L$6 -> 0 | I17: =(H$17-G17) -> 0 | K17: =IF(J$17="CLORURO DE POTASIO ESPECIFI",(($I$17/'Parametros de referencia'!$X$7)/'Parametros de referencia'!AI$7),0) -> 0 | L17: =$K$17*0.7 -> 0 | M17: 50 | O17: =$D$17*'Parametros de referencia'!$L$6 -> 0 | P17: =IF('Resultado Analisis suelos '!$B$25<40,"No Aplicar",IF(AND('Resultado Analisis suelos '!$B$25>40,'Resultado Analisis suelos '!$B$25<70),'Determinacion de Dosis'!O17*0.2,IF('Resultado Analisis suelos '!$B$25>=70,0.35*'Determinacion de Dosis'!O17,0))) -> #DIV/0! | Q17: =IF(J$17="CLORURO DE POTASIO ESPECIFI",(($P$17/'Parametros de referencia'!$X$7)/'Parametros de referencia'!AI$7),0) -> 0
B18: 2 | C18: =C$4 -> 0 | D18: =D$4 -> 0 | E18: ='Resultado Analisis suelos '!C$13 -> 0 | F18: =E18*'Parametros de referencia'!$C$11 -> 0 | G18: ='Parametros de referencia'!C$3*('Parametros de referencia'!$C$9*'Parametros de referencia'!C$4)*'Parametros de referencia'!$C$10*(F$18/'Parametros de referencia'!$C$17) -> 0 | H18: =D18*'Parametros de referencia'!$L$6 -> 0 | I18: =(H18-G18) -> 0 | K18: =IF(J$18="CLORURO DE POTASIO ESPECIFI",(($I$18/'Parametros de referencia'!$X$7)/'Parametros de referencia'!AI$7),0) -> 0 | L18: =$K$18*0.7 -> 0 | M18: 50 | O18: =$D$18*'Parametros de referencia'!$L$6 -> 0 | P18: =IF('Resultado Analisis suelos '!$C$25<40,"No Aplicar",IF(AND('Resultado Analisis suelos '!$C$25>40,'Resultado Analisis suelos '!$C$25<70),'Determinacion de Dosis'!O18*0.31,IF('Resultado Analisis suelos '!$C$25>=70,0.5*'Determinacion de Dosis'!O18,0))) -> #DIV/0! | Q18: =IF(J$18="CLORURO DE POTASIO ESPECIFI",(($P$18/'Parametros de referencia'!$X$7)/'Parametros de referencia'!AI$7),0) -> 0
B19: 3 | C19: =C$5 -> 0 | D19: =D$5 -> 0 | E19: ='Resultado Analisis suelos '!D$13 -> 0 | F19: =E19*'Parametros de referencia'!$C$11 -> 0 | G19: ='Parametros de referencia'!C$3*('Parametros de referencia'!$C$9*'Parametros de referencia'!C$4)*'Parametros de referencia'!$C$10*(F$19/'Parametros de referencia'!$C$17) -> 0 | H19: =D19*'Parametros de referencia'!$L$6 -> 0 | I19: =(H19-G19) -> 0 | K19: =IF(J$19="CLORURO DE POTASIO ESPECIFI",(($I$19/'Parametros de referencia'!$X$7)/'Parametros de referencia'!AI$7),0) -> 0 | L19: =$K$19*0.7 -> 0 | M19: 50 | O19: =$D$19*'Parametros de referencia'!$L$6 -> 0 | P19: =IF('Resultado Analisis suelos '!$D$25<40,"No Aplicar",IF(AND('Resultado Analisis suelos '!$D$25>40,'Resultado Analisis suelos '!$D$25<70),'Determinacion de Dosis'!O19*0.1,IF('Resultado Analisis suelos '!$D$25>=70,0.15*'Determinacion de Dosis'!O19,0))) -> #DIV/0! | Q19: =IF(J$19="CLORURO DE POTASIO ESPECIFI",(($P$19/'Parametros de referencia'!$X$7)/'Parametros de referencia'!AI$7),0) -> 0
A22: Calculo de Boro
A23: Suerte | B23: Zona | C23: Area Ha | D23: Productividad Est (ton/ha) | E23: P (ppm) | G23: Kg [B] /ha disponible suelo | H23: Kg/ha [B] demandado | I23: Dosis (Kg/ha [B]) | J23: Fertilizante | K23: Kg Fert/Ha | L23: Dosis Plantilla (Kg/Ha)
A24: =A3 -> 017002F | B24: 1 | C24: =C$3 -> 0 | D24: =D$3 -> 0 | E24: ='Resultado Analisis suelos '!B$20 -> 0 | G24: ='Parametros de referencia'!C$3*('Parametros de referencia'!$C$9*'Parametros de referencia'!C$4)*'Parametros de referencia'!$C$10*(E$24/'Parametros de referencia'!$C$17) -> 0 | H24: =(D24*'Parametros de referencia'!L$15)/1000 -> 0 | I24: =(H24-G24) -> 0 | K24: =IF(J$24="ZINCOFERTIL X 20KG",((I$24/'Parametros de referencia'!$AD$4)/'Parametros de referencia'!AI$4),IF(J$24="MICROFERTIL X 46KG",((I$24/'Parametros de referencia'!AD$5)/'Parametros de referencia'!AI$5),IF(J$24="BOROZINCO",((I$24/'Parametros de referencia'!AD$6)/'Parametros de referencia'!AI$6),IF(J$24="FERTICANA ESPECIFICACION",((I$24/'Parametros de referencia'!$AD$8)/'Parametros de referencia'!$AI$8),0)))) -> 0 | L24: =$K$24*0.7 -> 0
B25: 2 | C25: =C$4 -> 0 | D25: =D$4 -> 0 | E25: ='Resultado Analisis suelos '!C$20 -> 0 | G25: ='Parametros de referencia'!C$3*('Parametros de referencia'!$C$9*'Parametros de referencia'!C$4)*'Parametros de referencia'!$C$10*(E$25/'Parametros de referencia'!$C$17) -> 0 | H25: =(D25*'Parametros de referencia'!L$15)/1000 -> 0 | I25: =(H25-G25) -> 0 | K25: =IF(J$25="ZINCOFERTIL X 20KG",((I$25/'Parametros de referencia'!$AD$4)/'Parametros de referencia'!AI$4),IF(J$25="MICROFERTIL X 46KG",((I$25/'Parametros de referencia'!AD$5)/'Parametros de referencia'!AI$5),IF(J$25="BOROZINCO",((I$25/'Parametros de referencia'!AD$6)/'Parametros de referencia'!AI$6),IF(J$25="FERTICANA ESPECIFICACION",((I$25/'Parametros de referencia'!$AD$8)/'Parametros de referencia'!$AI$8),0)))) -> 0 | L25: =$K$25*0.7 -> 0
A29: Calculo de Zinc
A30: Suerte | B30: Zona | C30: Area Ha | D30: Productividad Est (ton/ha) | E30: P (ppm) | G30: Kg [Zn] /ha disponible suelo | H30: Kg/ha [Zn] demandado | I30: Dosis (Kg/ha [Zn]) | J30: Fertilizante | K30: Kg Fert/Ha | L30: Dosis Plantilla (Kg/Ha)
A31: =A3 -> 017002F | B31: 1 | C31: =C$3 -> 0 | D31: =D$3 -> 0 | E31: ='Resultado Analisis suelos '!B$19 -> 0 | G31: ='Parametros de referencia'!C$3*('Parametros de referencia'!$C$9*'Parametros de referencia'!C$4)*'Parametros de referencia'!$C$10*(E$31/'Parametros de referencia'!$C$17) -> 0 | H31: =($D$31*'Parametros de referencia'!L$14)/1000 -> 0 | I31: =(H31-G31) -> 0 | K31: =IF(J$31="ZINCOFERTIL X 20KG",((I$31/'Parametros de referencia'!$AF$4)/'Parametros de referencia'!AI$4),IF(J$31="MICROFERTIL X 46KG",((I$31/'Parametros de referencia'!AF$5)/'Parametros de referencia'!AI$5),IF(J$31="BOROZINCO",((I$31/'Parametros de referencia'!AF$6)/'Parametros de referencia'!AI$6),IF(J$31="FERTICANA ESPECIFICACION",((I$31/'Parametros de referencia'!$AF$8)/'Parametros de referencia'!$AI$8),0)))) -> 0 | L31: =$K$31*0.7 -> 0
B32: 2 | C32: =C$4 -> 0 | D32: =D$4 -> 0 | E32: ='Resultado Analisis suelos '!C$19 -> 0 | G32: ='Parametros de referencia'!C$3*('Parametros de referencia'!$C$9*'Parametros de referencia'!C$4)*'Parametros de referencia'!$C$10*(E$32/'Parametros de referencia'!$C$17) -> 0 | H32: =(D32*'Parametros de referencia'!L$14)/1000 -> 0 | I32: =(H32-G32) -> 0 | K32: =IF(J$32="ZINCOFERTIL X 20KG",((I$32/'Parametros de referencia'!$AF$4)/'Parametros de referencia'!AI$4),IF(J$32="MICROFERTIL X 46KG",((I$32/'Parametros de referencia'!AF$5)/'Parametros de referencia'!AI$5),IF(J$32="BOROZINCO",((I$32/'Parametros de referencia'!AF$6)/'Parametros de referencia'!AI$6),IF(J$32="FERTICANA ESPECIFICACION",((I$32/'Parametros de referencia'!$AF$8)/'Parametros de referencia'!$AI$8),0)))) -> 0 | L32: =$K$32*0.7 -> 0
A36: Calculo de Hierro
A37: Suerte | B37: Zona | C37: Area Ha | D37: Productividad Est (ton/ha) | E37: P (ppm) | G37: Kg [Zn] /ha disponible suelo | H37: Kg/ha [Zn] demandado | I37: Dosis (Kg/ha [Zn]) | J37: Fertilizante | K37: Kg Fert/Ha | L37: Dosis Plantilla (Kg/Ha)
A38: =A3 -> 017002F | B38: 1 | C38: =C$3 -> 0 | D38: =D$3 -> 0 | E38: ='Resultado Analisis suelos '!B$12 -> 0 | G38: ='Parametros de referencia'!C$3*('Parametros de referencia'!$C$9*'Parametros de referencia'!C$4)*'Parametros de referencia'!$C$10*(E$38/'Parametros de referencia'!$C$17) -> 0 | H38: =(D38*'Parametros de referencia'!$L$11)/1000 -> 0 | I38: =(H38-G38) -> 0 | K38: =IF(J$31="ZINCOFERTIL X 20KG",((I$31/'Parametros de referencia'!$AF$4)/'Parametros de referencia'!AI$4),IF(J$31="MICROFERTIL X 46KG",((I$31/'Parametros de referencia'!AF$5)/'Parametros de referencia'!AI$5),IF(J$31="BOROZINCO",((I$31/'Parametros de referencia'!AF$6)/'Parametros de referencia'!AI$6),IF(J$31="FERTICANA ESPECIFICACION",((I$31/'Parametros de referencia'!$AF$8)/'Parametros de referencia'!$AI$8),0)))) -> 0 | L38: =$K$31*0.7 -> 0
B39: 2 | C39: =C$4 -> 0 | D39: =D$4 -> 0 | E39: ='Resultado Analisis suelos '!C$12 -> 0 | G39: ='Parametros de referencia'!C$3*('Parametros de referencia'!$C$9*'Parametros de referencia'!C$4)*'Parametros de referencia'!$C$10*(E$39/'Parametros de referencia'!$C$17) -> 0 | H39: =(D39*'Parametros de referencia'!$L$11)/1000 -> 0 | I39: =(H39-G39)/1000 -> 0 | K39: =IF(J$32="ZINCOFERTIL X 20KG",((I$32/'Parametros de referencia'!$AF$4)/'Parametros de referencia'!AI$4),IF(J$32="MICROFERTIL X 46KG",((I$32/'Parametros de referencia'!AF$5)/'Parametros de referencia'!AI$5),IF(J$32="BOROZINCO",((I$32/'Parametros de referencia'!AF$6)/'Parametros de referencia'!AI$6),IF(J$32="FERTICANA ESPECIFICACION",((I$32/'Parametros de referencia'!$AF$8)/'Parametros de referencia'!$AI$8),0)))) -> 0 | L39: =$K$32*0.7 -> 0

Sheet Parametros de referencia
B1: Parametros del Suelo | F1: Factor de extraccion por Variedad | N1: Eficiencia de Fertilizantes Comité de AP | U1: Parametros Fertilizates | AI1: Eficiencias Seleccionada | AJ1: Eficiencias | AL1: Observaciones
B2: Parametros de referencia | C2: Valor | D2: Unidad | F2: Mayores (Kg / THC) | N2: Urea | P2: DAP | R2: K | U2: Fertilizante/ Nutrimento | V2: N | W2: P | X2: K | Y2: S | Z2: Ca | AA2: Si | AB2: C | AC2: Mg | AD2: B | AE2: Fe | AF2: Zn | AG2: Cu | AH2: Cl | AJ2: Alta | AK2: Baja
B3: Densidad aparente del suelo (ρ) | C3: 1.2 | D3: Ton/m3 | F3: Nutriente / Variedad | G3: CC 01-1940 | H3: CC 01-678 | I3: CC 05-430 | J3: CC 85-92 | K3: CC 93-4418 | L3: Promedio | N3: pH | P3: Ph | R3: (Ca+Mg)/K | U3: UREA ESPECIFICACION | V3: 0.46 | W3: - | X3: - | Y3: - | Z3: - | AA3: - | AB3: - | AC3: - | AD3: - | AE3: - | AF3: - | AG3: - | AH3: - | AI3: =IF(AND(AVERAGE('Resultado Analisis suelos '!B7:C7)>=6.5,AVERAGE('Resultado Analisis suelos '!B7:C7)<=7.5),'Parametros de referencia'!AJ3,'Parametros de referencia'!AK3) -> #DIV/0! | AJ3: 0.9 | AK3: 0.75 | AL3: Variacion por pH
B4: Profundidad de extraccion (h) | C4: 0.2 | D4: m | F4: Nitrogeno | G4: 0.82 | H4: 0.76 | I4: 0.68 | J4: 1.03 | K4: 1.18 | L4: =AVERAGE(G4:K4) -> 0.894 | N4: N Acido | O4: Salino | P4: 6,5 - 7,5 | Q4: >7,5 o ><6,5> | R4: >70 | S4: <70 | U4: ZINCOFERTIL X 20KG | V4: - | W4: - | X4: 0.03 | Y4: 0.06 | Z4: - | AA4: 0.18 | AB4: 0.094 | AC4: - | AD4: 0.03 | AE4: - | AF4: 0.15 | AG4: 0.006 | AH4: - | AI4: 1 | AJ4: 1 | AK4: 1
B5: Cantidad de N en la M.O | C5: 0.05 | D5: % | F5: Fosforo | G5: 0.17 | H5: 0.11 | I5: 0.11 | J5: 0.22 | K5: 0.24 | L5: =AVERAGE(G5:K5) -> 0.17 | N5: 0.8 | O5: 0.75 | P5: 0.5 | Q5: 0.3 | R5: 0.5 | S5: 0.75 | U5: MICROFERTIL X 46KG | V5: - | W5: 0.05 | X5: - | Y5: 0.058 | Z5: 0.18 | AA5: 0.25 | AB5: 0.05 | AC5: 0.03 | AD5: 0.01 | AE5: 0.01 | AF5: 0.03 | AG5: 0.002 | AH5: - | AI5: 1 | AJ5: 1 | AK5: 1
B6: Tasa de mineralizacion del N | C6: 0.01 | D6: % | F6: Potasio | G6: 1.01 | H6: 1.13 | I6: 1.05 | J6: 1.43 | K6: 1.51 | L6: =AVERAGE(G6:K6) -> 1.226 | U6: BOROZINCO | V6: 0.03 | W6: - | X6: - | Y6: 0.06 | Z6: - | AA6: 0.17 | AB6: - | AC6: - | AD6: 0.025 | AE6: - | AF6: 0.15 | AG6: 0.005 | AH6: - | AI6: 1 | AJ6: 1 | AK6: 1
B7: Absorcion de N del suelos | C7: 0.5 | D7: % | F7: Magnesio | G7: 0.2 | H7: 0.15 | I7: 0.15 | J7: 0.27 | K7: 0.32 | L7: =AVERAGE(G7:K7) -> 0.218 | N7: SULFATO AMONIO | P7: P | R7: K | U7: CLORURO DE POTASIO ESPECIFI | V7: - | W7: - | X7: 0.6 | Y7: - | Z7: - | AA7: - | AB7: - | AC7: - | AD7: - | AE7: - | AF7: - | AG7: - | AH7: 0.46 | AI7: =IF(AVERAGE('Resultado Analisis suelos '!B25:C25)<70,'Parametros de referencia'!AJ$7,'Parametros de referencia'!AK$7) -> #DIV/0! | AJ7: 0.75 | AK7: 0.5 | AL7: Variacion de Relacion (Ca+Mg)/K (>70) Alta - (<70) Baja
B8: Conversiones | F8: Calcio | G8: 0.41 | H8: 0.32 | I8: 0.34 | J8: 0.52 | K8: 0.64 | L8: =AVERAGE(G8:K8) -> 0.446 | N8: pH | P8: Ph | R8: (Ca+Mg)/K | U8: FERTICANA ESPECIFICACION | V8: - | W8: 0.03 | X8: 0.2 | Y8: 0.02 | Z8: 0.02 | AA8: - | AB8: - | AC8: 0.005 | AD8: 0.005 | AE8: 0.01 | AF8: 0.005 | AG8: - | AH8: - | AI8: 1 | AJ8: 1 | AK8: 1
B9: 1 Hectarea | C9: 10000 | D9: m2 | F9: Menores (gr/THC) | N9: N Acido | O9: Salino | P9: 6,5 - 7,5 | Q9: >7,5 o <6,5 | R9: >70 | S9: <70 | U9: FOSQUIMINT VEINTE-8 | V9: - | W9: 0.36 | X9: - | Z9: 0.25 | AA9: - | AB9: - | AC9: - | AD9: - | AE9: - | AF9: - | AG9: - | AH9: - | AI9: =IF(6.5<AVERAGE('Resultado Analisis suelos '!B7:C7)<7.5,'Parametros de referencia'!AJ9,'Parametros de referencia'!AK9) -> #DIV/0! | AJ9: 0.5 | AK9: 0.3
B10: 1 Tonelada | C10: 1000 | D10: Kg | F10: Azufre | G10: 0.08 | H10: 0.06 | I10: 0.05 | J10: 0.09 | K10: 0.06 | L10: =AVERAGE(G10:K10) -> 0.068 | N10: 0.8 | U10: SULFATO AMONIO-CAMPO ESPEC | V10: 0.21 | W10: - | X10: - | Y10: 0.24 | Z10: - | AA10: - | AB10: - | AC10: - | AD10: - | AE10: - | AF10: - | AG10: - | AH10: - | AI10: 1 | AJ10: 1 | AK10: 1
B11: 1 meq/100gr Suelo K+ | C11: 391 | D11: ppm | F11: Hierro | G11: 40.38 | H11: 36.62 | I11: 37.83 | J11: 66.1 | K11: 77.37 | L11: =AVERAGE(G11:K11) -> 51.66 | U11: SULFATO DE CALCIO ( YESO AGRICOLA) | V11: - | W11: - | X11: - | Y11: - | Z11: 0.26 | AA11: 0.012 | AB11: - | AC11: 0.014 | AD11: - | AE11: 0.001 | AF11: - | AG11: - | AH11: - | AI11: 1 | AJ11: 1 | AK11: 1
B12: 1 meq/100gr Suelo Ca+2 | C12: 200.4 | D12: ppm | F12: Manganeso | G12: 16.44 | H12: 3.38 | I12: 3.75 | J12: 19.03 | K12: 7.4 | L12: =AVERAGE(G12:K12) -> 10 | N12: NITRO XTEND | P12: P | R12: K | U12: NITRORGANIC FERT. ORGAN EMPRESAGRO | V12: 0.0466 | W12: 0.0305 | X12: 0.0302 | Y12: 0.03 | Z12: 0.1303 | AA12: 0.1674 | AB12: 0.2013 | AC12: - | AD12: - | AE12: - | AF12: - | AG12: - | AH12: - | AI12: 1 | AJ12: 1 | AK12: 1
B13: 1 meq/100gr Suelo Mg+2 | C13: 121.5 | D13: ppm | F13: Cobre | G13: 0.65 | H13: 0.46 | I13: 0.51 | J13: 0.78 | K13: 0.93 | L13: =AVERAGE(G13:K13) -> 0.666 | N13: pH | P13: Ph | R13: (Ca+Mg)/K | U13: NITRO XTEND | V13: 0.4 | W13: - | X13: - | Y13: 0.06 | Z13: - | AA13: - | AB13: - | AC13: - | AD13: - | AE13: - | AF13: - | AG13: - | AH13: - | AI13: =IF(6.5<AVERAGE('Resultado Analisis suelos '!B7:C7)<7.5,'Parametros de referencia'!AJ3,'Parametros de referencia'!AK3) -> #DIV/0! | AJ13: 0.9 | AK13: 0.75
B14: 1 meq/100gr Suelo Na+ | C14: 229 | D14: ppm | F14: Zinc | G14: 0.73 | H14: 0.92 | I14: 0.91 | J14: 1.25 | K14: 1.27 | L14: =AVERAGE(G14:K14) -> 1.016 | N14: N Acido | O14: Salino | P14: 6,5 - 7,5 | Q14: >7,5 o <6,5 | R14: >70 | S14: <70 | U14: FOSFATO DIAMONICO (DAP) | V14: 0.18 | W14: 0.46 | X14: - | Y14: - | Z14: - | AA14: - | AB14: - | AC14: - | AD14: - | AE14: - | AF14: - | AG14: - | AH14: - | AI14: =IF(6.5<AVERAGE('Resultado Analisis suelos '!B7:C7)<7.5,'Parametros de referencia'!AJ14,'Parametros de referencia'!AK14) -> #DIV/0! | AJ14: 0.5 | AK14: 0.3 | AL14: Variacion de pH (6,5-7,5) Alta - (>7,5 o <6,5) Baja
B15: 1 meq/100gr Suelo AL+3 | C15: 89.9 | D15: ppm | F15: Boro | G15: 0.47 | H15: 0.48 | I15: 0.43 | J15: 0.61 | K15: 0.67 | L15: =AVERAGE(G15:K15) -> 0.532 | N15: 0.9 | O15: 0.75 | P15: 0.5 | Q15: 0.3 | R15: 0.5 | S15: 0.75 | U15: SUPER FOSFATO TRIPLE | V15: - | W15: 0.46 | X15: - | Y15: - | Z15: - | AA15: - | AB15: - | AC15: - | AD15: - | AE15: - | AF15: - | AG15: - | AH15: - | AI15: =IF(6.5<AVERAGE('Resultado Analisis suelos '!B7:C7)<7.5,'Parametros de referencia'!AJ14,'Parametros de referencia'!AK14) -> #DIV/0! | AJ15: 0.5 | AK15: 0.3
B16: 1 meq/100gr Suelo Zn+2 | C16: 327 | D16: ppm
B17: 1Kg | C17: 1000000 | D17: mg
U21: NITROGENO
U22: UREA ESPECIFICACION
U23: SULFATO AMONIO-CAMPO ESPEC
U24: NITRO XTEND
U26: FOSFORO
U27: FOSFATO DIAMONICO (DAP)
U28: FOSQUIMINT VEINTE-8
U30: POTASIO
U31: CLORURO DE POTASIO ESPECIFI
U33: MENORES
U34: ZINCOFERTIL X 20KG
U35: MICROFERTIL X 46KG
... U37: FERTICANA ESPECIFICACION
